Workbook

Sheet Summary
A1: Project Atlas: Leveraged Buyout Model
A2: ($ in millions) | FICTIONAL company with illustrative assumptions | educational model, not investment advice
A4: TRANSACTION | D4: RETURNS (selected exit year)
A5: Scenario (1 Base / 2 Up / 3 Down) | B5: =Assumptions!$C$7 -> 1 | D5: Exit year | G5: =Assumptions!$C$20 -> 5
A6: Entry EV | B6: =Transaction!$C$9 -> 1100 | D6: Exit multiple | G6: =Assumptions!$C$21 -> 11
A7: Entry EV / LTM EBITDA | B7: =Transaction!$C$8 -> 11 | D7: Sponsor IRR | G7: =Returns!C23 -> 0.15882954
A8: Entry EV / LTM revenue | B8: =Transaction!$C$10 -> 2.2 | D8: Sponsor MOIC | G8: =Returns!C22 -> 2.0897666
A9: Total leverage at close (x EBITDA) | B9: =(Transaction!$C$13+Transaction!$C$14+Transaction!$C$15)/Transaction!$C$7 -> 5.5 | D9: Sponsor proceeds | G9: =Returns!C21 -> 1269.7945
A10: Sponsor equity | B10: =Transaction!$C$16 -> 607.625 | D10: Model integrity | G10: =Checks!C15 -> ALL OK
A11: Equity % of capitalisation | B11: =Transaction!$C$27 -> 0.52488932
A13: SOURCES & USES
A14: Revolver | B14: =Transaction!$C$13 -> 0 | C14: =Transaction!$E$13 -> 0 | D14: Purchase of enterprise | G14: =Transaction!$C$20 -> 1100 | H14: =Transaction!$E$20 -> 11
A15: Term Loan B | B15: =Transaction!$C$14 -> 400 | C15: =Transaction!$E$14 -> 4 | D15: Transaction fees | G15: =Transaction!$C$21 -> 22 | H15: =Transaction!$E$21 -> 0.22
A16: Senior notes | B16: =Transaction!$C$15 -> 150 | C16: =Transaction!$E$15 -> 1.5 | D16: Financing fees | G16: =Transaction!$C$22 -> 15.625 | H16: =Transaction!$E$22 -> 0.15625
A17: Sponsor equity | B17: =Transaction!$C$16 -> 607.625 | C17: =Transaction!$E$16 -> 6.07625 | D17: Minimum cash | G17: =Transaction!$C$23 -> 20 | H17: =Transaction!$E$23 -> 0.2
A18: Total sources | B18: =Transaction!$C$17 -> 1157.625 | C18: =Transaction!$E$17 -> 11.57625 | D18: Total uses | G18: =Transaction!$C$24 -> 1157.625 | H18: =Transaction!$E$24 -> 11.57625
A20: FINANCIAL SUMMARY
B21: Close | C21: Year 1 | D21: Year 2 | E21: Year 3 | F21: Year 4 | G21: Year 5
A22: Revenue | B22: ='Operating Model'!C7 -> 500 | C22: ='Operating Model'!D7 -> 535 | D22: ='Operating Model'!E7 -> 572.45 | E22: ='Operating Model'!F7 -> 606.797 | F22: ='Operating Model'!G7 -> 643.20482 | G22: ='Operating Model'!H7 -> 675.36506
A23: % growth | C23: ='Operating Model'!D8 -> 0.07 | D23: ='Operating Model'!E8 -> 0.07 | E23: ='Operating Model'!F8 -> 0.06 | F23: ='Operating Model'!G8 -> 0.06 | G23: ='Operating Model'!H8 -> 0.05
A24: EBITDA | B24: ='Operating Model'!C9 -> 100 | C24: ='Operating Model'!D9 -> 109.675 | D24: ='Operating Model'!E9 -> 120.2145 | E24: ='Operating Model'!F9 -> 130.46135 | F24: ='Operating Model'!G9 -> 141.50506 | G24: ='Operating Model'!H9 -> 148.58031
A25: % margin | B25: ='Operating Model'!C10 -> 0.2 | C25: ='Operating Model'!D10 -> 0.205 | D25: ='Operating Model'!E10 -> 0.21 | E25: ='Operating Model'!F10 -> 0.215 | F25: ='Operating Model'!G10 -> 0.22 | G25: ='Operating Model'!H10 -> 0.22
A26: Free cash flow (after debt service) | C26: ='Operating Model'!D33 -> 24.713125 | D26: ='Operating Model'!E33 -> 34.512579 | E26: ='Operating Model'!F33 -> 45.521993 | F26: ='Operating Model'!G33 -> 55.279333 | G26: ='Operating Model'!H33 -> 62.963931
A27: Net debt | B27: ='Debt Schedule'!C35 -> 530 | C27: ='Debt Schedule'!D35 -> 505.28688 | D27: ='Debt Schedule'!E35 -> 470.7743 | E27: ='Debt Schedule'!F35 -> 425.2523 | F27: ='Debt Schedule'!G35 -> 369.97297 | G27: ='Debt Schedule'!H35 -> 307.00904
A28: Net debt / EBITDA | B28: ='Credit Stats'!C8 -> 5.3 | C28: ='Credit Stats'!D8 -> 4.607129 | D28: ='Credit Stats'!E8 -> 3.9161191 | E28: ='Credit Stats'!F8 -> 3.2596036 | F28: ='Credit Stats'!G8 -> 2.6145565 | G28: ='Credit Stats'!H8 -> 2.0662834
A29: EBITDA / cash interest | C29: ='Credit Stats'!D12 -> 2.4237569 | D29: ='Credit Stats'!E12 -> 2.8097422 | E29: ='Credit Stats'!F12 -> 3.2942263 | F29: ='Credit Stats'!G12 -> 3.8694193 | G29: ='Credit Stats'!H12 -> 4.5290514
A30: Covenant status | C30: ='Credit Stats'!D24 -> OK | D30: ='Credit Stats'!E24 -> OK | E30: ='Credit Stats'!F24 -> OK | F30: ='Credit Stats'!G24 -> OK | G30: ='Credit Stats'!H24 -> OK

Sheet Assumptions
A1: Assumptions & Inputs
A2: ($ in millions unless stated) | Project Atlas is a FICTIONAL company; all inputs are illustrative
A3: Legend: blue = input you can change · black = formula · green = link to another sheet · yellow fill = key deal lever
B4: Unit | C4: Close / LTM | D4: Year 1 | E4: Year 2 | F4: Year 3 | G4: Year 4 | H4: Year 5 | I4: Basis / source
A6: GENERAL
A7: Operating scenario (1 = Base, 2 = Upside, 3 = Downside) | C7: 1 | I7: Scenario switch: drives the whole workbook live
A8: LTM revenue | C8: 500 | I8: Illustrative assumption (fictional company)
A9: LTM EBITDA | C9: 100 | I9: Illustrative assumption: 20% LTM EBITDA margin
A10: Net PP&E at close | C10: 200 | I10: Illustrative assumption; used for the opening balance sheet
A12: TRANSACTION
A13: Entry EV / LTM EBITDA | C13: 11 | I13: Illustrative; mid-market industrial services deals typically price ~9x to 13x
A14: Transaction fees (% of EV) | C14: 0.02 | I14: Advisory, legal, diligence; capitalised into goodwill (simplification)
A15: Financing fees (% of debt raised + revolver commitment) | C15: 0.025 | I15: Underwriting / OID proxy; capitalised and amortised straight-line, tax-deductible
A16: Financing fee amortisation period (years) | C16: 7 | I16: Matches Term Loan B tenor
A17: Minimum cash (funded at close) | C17: 20 | I17: Operating cash buffer; revolver funds any shortfall below this level
A19: EXIT
A20: Exit year (1 to 5) | C20: 5 | I20: Hold period in years (1 to 5)
A21: Exit EV / EBITDA | C21: 11 | I21: Base case assumes NO multiple expansion (exit = entry)
A22: Management incentive plan (% of equity gain) | C22: 0.08 | I22: Illustrative; applied to the equity gain at exit
A24: FINANCING
A25: Revolver commitment | C25: 75 | I25: Illustrative revolving credit facility size
A26: Revolver drawn at close | C26: 0 | I26: Undrawn at close
A27: Revolver spread over SOFR | C27: 0.035 | I27: Illustrative
A28: Revolver undrawn commitment fee | C28: 0.005 | I28: Illustrative
A29: Term Loan B (x LTM EBITDA) | C29: 4 | I29: Illustrative senior secured leverage
A30: Term Loan B spread over SOFR | C30: 0.0375 | I30: Illustrative spread for a single-B credit
A31: Term Loan B mandatory amortisation (% of original, p.a.) | C31: 0.01 | I31: Standard 1% p.a. mandatory amortisation
A32: Excess cash flow sweep to Term Loan B | C32: 0.75 | I32: Excess cash flow sweep; remainder builds on balance sheet
A33: Senior unsecured notes (x LTM EBITDA) | C33: 1.5 | I33: Illustrative junior leverage; bullet maturity, non-callable in model
A34: Senior notes fixed coupon | C34: 0.0925 | I34: Illustrative fixed coupon
A35: Interest rate earned on cash | C35: 0.02 | I35: Interest on beginning-of-year cash
A37: TAX AND OPERATING
A38: Cash tax rate | C38: 0.25 | I38: Blended federal + state, illustrative
A39: Apply 163(j)-style interest cap (1 = yes) | C39: 1 | I39: 1 = deduct at most cap% x EBITDA of net interest; disallowed amount is lost (no carry-forward, conservative)
A40: Interest deduction cap (% of EBITDA) | C40: 0.3 | I40: Section 163(j) uses ~30% of adjusted taxable income
A41: D&A (% of revenue) | C41: 0.035 | I41: Illustrative
A42: Capex (% of revenue) | C42: 0.04 | I42: Illustrative; above D&A = growth capex
A43: Net working capital (% of revenue) | C43: 0.12 | I43: Illustrative; cash is absorbed as revenue grows
A45: TIME-SERIES INPUTS
A46: SOFR forward curve | D46: 0.04 | E46: 0.0375 | F46: 0.035 | G46: 0.035 | H46: 0.035 | I46: Illustrative forward curve; Term Loan B and revolver float over this
...

Sheet Transaction
A1: Transaction: Sources & Uses
A2: ($ in millions unless stated) | Project Atlas is a FICTIONAL company; all inputs are illustrative
C4: $mm | D4: % of total | E4: x LTM EBITDA
A6: PURCHASE PRICE | G6: Note: sponsor equity is the balancing item. Transaction fees are capitalised into goodwill for simplicity.
A7: LTM EBITDA | C7: =Assumptions!$C$9 -> 100
A8: Entry multiple (EV / LTM EBITDA) | C8: =Assumptions!$C$13 -> 11
A9: Enterprise value (cash-free, debt-free) | C9: =C7*C8 -> 1100
A10: EV / LTM revenue | C10: =C9/Assumptions!$C$8 -> 2.2
A12: SOURCES OF FUNDS
A13: Revolver (drawn) | C13: =Assumptions!$C$26 -> 0 | D13: =C13/C$17 -> 0 | E13: =C13/C$7 -> 0
A14: Term Loan B | C14: =Assumptions!$C$29*C7 -> 400 | D14: =C14/C$17 -> 0.34553504 | E14: =C14/C$7 -> 4
A15: Senior unsecured notes | C15: =Assumptions!$C$33*C7 -> 150 | D15: =C15/C$17 -> 0.12957564 | E15: =C15/C$7 -> 1.5
A16: Sponsor equity (plug) | C16: =C24-C13-C14-C15 -> 607.625 | D16: =C16/C$17 -> 0.52488932 | E16: =C16/C$7 -> 6.07625
A17: Total sources | C17: =SUM(C13:C16) -> 1157.625 | D17: =C17/C$17 -> 1 | E17: =C17/C$7 -> 11.57625
A19: USES OF FUNDS
A20: Purchase of enterprise | C20: =C9 -> 1100 | D20: =C20/C$24 -> 0.95022136 | E20: =C20/C$7 -> 11
A21: Transaction fees | C21: =Assumptions!$C$14*C9 -> 22 | D21: =C21/C$24 -> 0.019004427 | E21: =C21/C$7 -> 0.22
A22: Financing fees (capitalised) | C22: =(Assumptions!$C$29*C7+Assumptions!$C$33*C7+Assumptions!$C$25)*Assumptions!$C$15 -> 15.625 | D22: =C22/C$24 -> 0.013497462 | E22: =C22/C$7 -> 0.15625
A23: Cash to balance sheet (minimum cash) | C23: =Assumptions!$C$17 -> 20 | D23: =C23/C$24 -> 0.017276752 | E23: =C23/C$7 -> 0.2
A24: Total uses | C24: =SUM(C20:C23) -> 1157.625 | D24: =C24/C$24 -> 1 | E24: =C24/C$7 -> 11.57625
A26: DERIVED
A27: Sponsor equity as % of total capitalisation | C27: =C16/C17 -> 0.52488932
A28: Opening net working capital | C28: =Assumptions!$C$43*Assumptions!$C$8 -> 60
A29: Goodwill created (EV + fees - NWC - net PP&E) | C29: =C20+C21-C28-Assumptions!$C$10 -> 862
A30: Annual financing fee amortisation | C30: =C22/Assumptions!$C$16 -> 2.2321429

Sheet Operating Model
A1: Operating Model: Income Statement & Cash Flow
A2: ($ in millions unless stated) | Project Atlas is a FICTIONAL company; all inputs are illustrative
B4: Unit | C4: Close / LTM | D4: Year 1 | E4: Year 2 | F4: Year 3 | G4: Year 4 | H4: Year 5
A6: INCOME STATEMENT
A7: Revenue | B7: $mm | C7: =Assumptions!$C$8 -> 500 | D7: =C7*(1+Assumptions!D56) -> 535 | E7: =D7*(1+Assumptions!E56) -> 572.45 | F7: =E7*(1+Assumptions!F56) -> 606.797 | G7: =F7*(1+Assumptions!G56) -> 643.20482 | H7: =G7*(1+Assumptions!H56) -> 675.36506
A8: % growth | B8: % | D8: =D7/C7-1 -> 0.07 | E8: =E7/D7-1 -> 0.07 | F8: =F7/E7-1 -> 0.06 | G8: =G7/F7-1 -> 0.06 | H8: =H7/G7-1 -> 0.05
A9: EBITDA | B9: $mm | C9: =Assumptions!$C$9 -> 100 | D9: =D7*Assumptions!D57 -> 109.675 | E9: =E7*Assumptions!E57 -> 120.2145 | F9: =F7*Assumptions!F57 -> 130.46135 | G9: =G7*Assumptions!G57 -> 141.50506 | H9: =H7*Assumptions!H57 -> 148.58031
A10: % margin | B10: % | C10: =C9/C7 -> 0.2 | D10: =D9/D7 -> 0.205 | E10: =E9/E7 -> 0.21 | F10: =F9/F7 -> 0.215 | G10: =G9/G7 -> 0.22 | H10: =H9/H7 -> 0.22
A11: Less: depreciation & amortisation | B11: $mm | D11: =D7*Assumptions!$C$41 -> 18.725 | E11: =E7*Assumptions!$C$41 -> 20.03575 | F11: =F7*Assumptions!$C$41 -> 21.237895 | G11: =G7*Assumptions!$C$41 -> 22.512169 | H11: =H7*Assumptions!$C$41 -> 23.637777
A12: EBIT | B12: $mm | D12: =D9-D11 -> 90.95 | E12: =E9-E11 -> 100.17875 | F12: =F9-F11 -> 109.22346 | G12: =G9-G11 -> 118.99289 | H12: =H9-H11 -> 124.94254
A13: Less: cash interest expense (incl. undrawn fees) | B13: $mm | D13: ='Debt Schedule'!D45 -> 45.25 | E13: ='Debt Schedule'!E45 -> 42.784887 | F13: ='Debt Schedule'!F45 -> 39.603033 | G13: ='Debt Schedule'!G45 -> 36.570102 | H13: ='Debt Schedule'!H45 -> 32.806056
A14: Plus: interest income | B14: $mm | D14: ='Debt Schedule'!D46 -> 0.4 | E14: ='Debt Schedule'!E46 -> 0.50356563 | F14: ='Debt Schedule'!F46 -> 0.5784543 | G14: ='Debt Schedule'!G46 -> 0.65222354 | H14: ='Debt Schedule'!H46 -> 0.71945255
A15: Less: amortisation of financing fees | B15: $mm | D15: =Transaction!$C$30 -> 2.2321429 | E15: =Transaction!$C$30 -> 2.2321429 | F15: =Transaction!$C$30 -> 2.2321429 | G15: =Transaction!$C$30 -> 2.2321429 | H15: =Transaction!$C$30 -> 2.2321429
A16: Pre-tax income | B16: $mm | D16: =D12-D13+D14-D15 -> 43.867857 | E16: =E12-E13+E14-E15 -> 55.665286 | F16: =F12-F13+F14-F15 -> 67.966738 | G16: =G12-G13+G14-G15 -> 80.84287 | H16: =H12-H13+H14-H15 -> 90.62379
A18: TAX CALCULATION
A19: Net interest expense (incl. fee amortisation) | B19: $mm | D19: =D13+D15-D14 -> 47.082143 | E19: =E13+E15-E14 -> 44.513464 | F19: =F13+F15-F14 -> 41.256722 | G19: =G13+G15-G14 -> 38.150022 | H19: =H13+H15-H14 -> 34.318746
A20: Deductible interest cap (cap % x EBITDA) | B20: $mm | D20: =IF(Assumptions!$C$39=1,MIN(D19,Assumptions!$C$40*D9),D19) -> 32.9025 | E20: =IF(Assumptions!$C$39=1,MIN(E19,Assumptions!$C$40*E9),E19) -> 36.06435 | F20: =IF(Assumptions!$C$39=1,MIN(F19,Assumptions!$C$40*F9),F19) -> 39.138407 | G20: =IF(Assumptions!$C$39=1,MIN(G19,Assumptions!$C$40*G9),G19) -> 38.150022 | H20: =IF(Assumptions!$C$39=1,MIN(H19,Assumptions!$C$40*H9),H19) -> 34.318746
A21: Disallowed interest (added back for tax) | B21: $mm | D21: =D19-D20 -> 14.179643 | E21: =E19-E20 -> 8.449114 | F21: =F19-F20 -> 2.1183154 | G21: =G19-G20 -> 0 | H21: =H19-H20 -> 0
A22: Taxable income | B22: $mm | D22: =D16+D21 -> 58.0475 | E22: =E16+E21 -> 64.1144 | F22: =F16+F21 -> 70.085054 | G22: =G16+G21 -> 80.84287 | H22: =H16+H21 -> 90.62379
A23: Cash taxes | B23: $mm | D23: =MAX(0,D22)*Assumptions!$C$38 -> 14.511875 | E23: =MAX(0,E22)*Assumptions!$C$38 -> 16.0286 | F23: =MAX(0,F22)*Assumptions!$C$38 -> 17.521263 | G23: =MAX(0,G22)*Assumptions!$C$38 -> 20.210718 | H23: =MAX(0,H22)*Assumptions!$C$38 -> 22.655948
A24: Net income | B24: $mm | D24: =D16-D23 -> 29.355982 | E24: =E16-E23 -> 39.636686 | F24: =F16-F23 -> 50.445475 | G24: =G16-G23 -> 60.632153 | H24: =H16-H23 -> 67.967843
A26: CASH FLOW
A27: Net income | B27: $mm | D27: =D24 -> 29.355982 | E27: =E24 -> 39.636686 | F27: =F24 -> 50.445475 | G27: =G24 -> 60.632153 | H27: =H24 -> 67.967843
A28: Plus: D&A | B28: $mm | D28: =D11 -> 18.725 | E28: =E11 -> 20.03575 | F28: =F11 -> 21.237895 | G28: =G11 -> 22.512169 | H28: =H11 -> 23.637777
A29: Plus: financing fee amortisation (non-cash) | B29: $mm | D29: =D15 -> 2.2321429 | E29: =E15 -> 2.2321429 | F29: =F15 -> 2.2321429 | G29: =G15 -> 2.2321429 | H29: =H15 -> 2.2321429
A30: Net working capital (balance) | B30: $mm | C30: =Assumptions!$C$43*C7 -> 60 | D30: =Assumptions!$C$43*D7 -> 64.2 | E30: =Assumptions!$C$43*E7 -> 68.694 | F30: =Assumptions!$C$43*F7 -> 72.81564 | G30: =Assumptions!$C$43*G7 -> 77.184578 | H30: =Assumptions!$C$43*H7 -> 81.043807
A31: Less: increase in NWC | B31: $mm | D31: =D30-C30 -> 4.2 | E31: =E30-D30 -> 4.494 | F31: =F30-E30 -> 4.12164 | G31: =G30-F30 -> 4.3689384 | H31: =H30-G30 -> 3.8592289
A32: Less: capital expenditures | B32: $mm | D32: =D7*Assumptions!$C$42 -> 21.4 | E32: =E7*Assumptions!$C$42 -> 22.898 | F32: =F7*Assumptions!$C$42 -> 24.27188 | G32: =G7*Assumptions!$C$42 -> 25.728193 | H32: =H7*Assumptions!$C$42 -> 27.014602
A33: Free cash flow available for debt repayment | B33: $mm | D33: =D27+D28+D29-D31-D32 -> 24.713125 | E33: =E27+E28+E29-E31-E32 -> 34.512579 | F33: =F27+F28+F29-F31-F32 -> 45.521993 | G33: =G27+G28+G29-G31-G32 -> 55.279333 | H33: =H27+H28+H29-H31-H32 -> 62.963931
A34: FCF / EBITDA | B34: % | D34: =D33/D9 -> 0.22533052 | E34: =E33/E9 -> 0.28709165 | F34: =F33/F9 -> 0.34893086 | G34: =G33/G9 -> 0.39065269 | H34: =H33/H9 -> 0.42377035
A36: UNLEVERED FREE CASH FLOW (memo)
A37: Unlevered taxes (EBIT x tax rate) | B37: $mm | D37: =D12*Assumptions!$C$38 -> 22.7375 | E37: =E12*Assumptions!$C$38 -> 25.044687 | F37: =F12*Assumptions!$C$38 -> 27.305865 | G37: =G12*Assumptions!$C$38 -> 29.748223 | H37: =H12*Assumptions!$C$38 -> 31.235634
A38: Unlevered free cash flow | B38: $mm | D38: =D9-D37-D32-D31 -> 61.3375 | E38: =E9-E37-E32-E31 -> 67.777812 | F38: =F9-F37-F32-F31 -> 74.76197 | G38: =G9-G37-G32-G31 -> 81.659706 | H38: =H9-H37-H32-H31 -> 86.470848

Sheet Debt Schedule
A1: Debt Schedule & Cash Sweep
A2: ($ in millions unless stated) | Project Atlas is a FICTIONAL company; all inputs are illustrative
B4: Unit | C4: Close / LTM | D4: Year 1 | E4: Year 2 | F4: Year 3 | G4: Year 4 | H4: Year 5
A6: CASH WATERFALL
A7: Beginning cash | B7: $mm | D7: =C15 -> 20 | E7: =D15 -> 25.178281 | F7: =E15 -> 28.922715 | G7: =F15 -> 32.611177 | H7: =G15 -> 35.972627
A8: Plus: free cash flow (after interest and taxes) | B8: $mm | D8: ='Operating Model'!D33 -> 24.713125 | E8: ='Operating Model'!E33 -> 34.512579 | F8: ='Operating Model'!F33 -> 45.521993 | G8: ='Operating Model'!G33 -> 55.279333 | H8: ='Operating Model'!H33 -> 62.963931
A9: Less: mandatory Term Loan B amortisation | B9: $mm | D9: =D25 -> 4 | E9: =E25 -> 4 | F9: =F25 -> 4 | G9: =G25 -> 4 | H9: =H25 -> 4
A10: Less: minimum cash | B10: $mm | D10: =Assumptions!$C$17 -> 20 | E10: =Assumptions!$C$17 -> 20 | F10: =Assumptions!$C$17 -> 20 | G10: =Assumptions!$C$17 -> 20 | H10: =Assumptions!$C$17 -> 20
A11: Cash available for revolver / sweep (negative = shortfall) | B11: $mm | D11: =D7+D8-D9-D10 -> 20.713125 | E11: =E7+E8-E9-E10 -> 35.69086 | F11: =F7+F8-F9-F10 -> 50.444708 | G11: =G7+G8-G9-G10 -> 63.89051 | H11: =H7+H8-H9-H10 -> 74.936559
A12: Revolver draw / (repayment) | B12: $mm | D12: =IF(D11<0,MIN(-D11,Assumptions!$C$25-D18),-MIN(D18,D11)) -> 0 | E12: =IF(E11<0,MIN(-E11,Assumptions!$C$25-E18),-MIN(E18,E11)) -> 0 | F12: =IF(F11<0,MIN(-F11,Assumptions!$C$25-F18),-MIN(F18,F11)) -> 0 | G12: =IF(G11<0,MIN(-G11,Assumptions!$C$25-G18),-MIN(G18,G11)) -> 0 | H12: =IF(H11<0,MIN(-H11,Assumptions!$C$25-H18),-MIN(H18,H11)) -> 0
A13: Cash available for sweep | B13: $mm | D13: =MAX(0,D11+D12) -> 20.713125 | E13: =MAX(0,E11+E12) -> 35.69086 | F13: =MAX(0,F11+F12) -> 50.444708 | G13: =MAX(0,G11+G12) -> 63.89051 | H13: =MAX(0,H11+H12) -> 74.936559
A14: Term Loan B cash sweep | B14: $mm | D14: =D26 -> 15.534844 | E14: =E26 -> 26.768145 | F14: =F26 -> 37.833531 | G14: =G26 -> 47.917882 | H14: =H26 -> 56.202419
A15: Ending cash | B15: $mm | C15: =Transaction!$C$23 -> 20 | D15: =D7+D8-D9+D12-D14 -> 25.178281 | E15: =E7+E8-E9+E12-E14 -> 28.922715 | F15: =F7+F8-F9+F12-F14 -> 32.611177 | G15: =G7+G8-G9+G12-G14 -> 35.972627 | H15: =H7+H8-H9+H12-H14 -> 38.73414
A17: REVOLVER
A18: Beginning balance | B18: $mm | D18: =C20 -> 0 | E18: =D20 -> 0 | F18: =E20 -> 0 | G18: =F20 -> 0 | H18: =G20 -> 0
A19: Draw / (repayment) | B19: $mm | D19: =D12 -> 0 | E19: =E12 -> 0 | F19: =F12 -> 0 | G19: =G12 -> 0 | H19: =H12 -> 0
A20: Ending balance | B20: $mm | C20: =Transaction!$C$13 -> 0 | D20: =D18+D19 -> 0 | E20: =E18+E19 -> 0 | F20: =F18+F19 -> 0 | G20: =G18+G19 -> 0 | H20: =H18+H19 -> 0
A21: Undrawn availability | B21: $mm | C21: =Assumptions!$C$25-C20 -> 75 | D21: =Assumptions!$C$25-D20 -> 75 | E21: =Assumptions!$C$25-E20 -> 75 | F21: =Assumptions!$C$25-F20 -> 75 | G21: =Assumptions!$C$25-G20 -> 75 | H21: =Assumptions!$C$25-H20 -> 75
A23: TERM LOAN B
A24: Beginning balance | B24: $mm | D24: =C27 -> 400 | E24: =D27 -> 380.46516 | F24: =E27 -> 349.69701 | G24: =F27 -> 307.86348 | H24: =G27 -> 255.9456
A25: Mandatory amortisation | B25: $mm | D25: =MIN(D24,Assumptions!$C$31*$C27) -> 4 | E25: =MIN(E24,Assumptions!$C$31*$C27) -> 4 | F25: =MIN(F24,Assumptions!$C$31*$C27) -> 4 | G25: =MIN(G24,Assumptions!$C$31*$C27) -> 4 | H25: =MIN(H24,Assumptions!$C$31*$C27) -> 4
A26: Cash sweep | B26: $mm | D26: =MIN(D24-D25,Assumptions!$C$32*D13) -> 15.534844 | E26: =MIN(E24-E25,Assumptions!$C$32*E13) -> 26.768145 | F26: =MIN(F24-F25,Assumptions!$C$32*F13) -> 37.833531 | G26: =MIN(G24-G25,Assumptions!$C$32*G13) -> 47.917882 | H26: =MIN(H24-H25,Assumptions!$C$32*H13) -> 56.202419
A27: Ending balance | B27: $mm | C27: =Transaction!$C$14 -> 400 | D27: =D24-D25-D26 -> 380.46516 | E27: =E24-E25-E26 -> 349.69701 | F27: =F24-F25-F26 -> 307.86348 | G27: =G24-G25-G26 -> 255.9456 | H27: =H24-H25-H26 -> 195.74318
A29: SENIOR UNSECURED NOTES (bullet)
A30: Beginning balance | B30: $mm | D30: =C31 -> 150 | E30: =D31 -> 150 | F30: =E31 -> 150 | G30: =F31 -> 150 | H30: =G31 -> 150
A31: Ending balance | B31: $mm | C31: =Transaction!$C$15 -> 150 | D31: =D30 -> 150 | E31: =E30 -> 150 | F31: =F30 -> 150 | G31: =G30 -> 150 | H31: =H30 -> 150
A33: TOTALS
A34: Total debt | C34: =C20+C27+C31 -> 550 | D34: =D20+D27+D31 -> 530.46516 | E34: =E20+E27+E31 -> 499.69701 | F34: =F20+F27+F31 -> 457.86348 | G34: =G20+G27+G31 -> 405.9456 | H34: =H20+H27+H31 -> 345.74318
A35: Net debt (total debt less cash) | C35: =C34-C15 -> 530 | D35: =D34-D15 -> 505.28688 | E35: =E34-E15 -> 470.7743 | F35: =F34-F15 -> 425.2523 | G35: =G34-G15 -> 369.97297 | H35: =H34-H15 -> 307.00904
A37: INTEREST (on beginning balances, no circularity)
A38: SOFR | B38: % | D38: =Assumptions!D46 -> 0.04 | E38: =Assumptions!E46 -> 0.0375 | F38: =Assumptions!F46 -> 0.035 | G38: =Assumptions!G46 -> 0.035 | H38: =Assumptions!H46 -> 0.035
A39: Revolver all-in rate | B39: % | D39: =D38+Assumptions!$C$27 -> 0.075 | E39: =E38+Assumptions!$C$27 -> 0.0725 | F39: =F38+Assumptions!$C$27 -> 0.07 | G39: =G38+Assumptions!$C$27 -> 0.07 | H39: =H38+Assumptions!$C$27 -> 0.07
A40: Term Loan B all-in rate | B40: % | D40: =D38+Assumptions!$C$30 -> 0.0775 | E40: =E38+Assumptions!$C$30 -> 0.075 | F40: =F38+Assumptions!$C$30 -> 0.0725 | G40: =G38+Assumptions!$C$30 -> 0.0725 | H40: =H38+Assumptions!$C$30 -> 0.0725
A41: Revolver interest | B41: $mm | D41: =D18*D39 -> 0 | E41: =E18*E39 -> 0 | F41: =F18*F39 -> 0 | G41: =G18*G39 -> 0 | H41: =H18*H39 -> 0
A42: Revolver undrawn fee | B42: $mm | D42: =(Assumptions!$C$25-D18)*Assumptions!$C$28 -> 0.375 | E42: =(Assumptions!$C$25-E18)*Assumptions!$C$28 -> 0.375 | F42: =(Assumptions!$C$25-F18)*Assumptions!$C$28 -> 0.375 | G42: =(Assumptions!$C$25-G18)*Assumptions!$C$28 -> 0.375 | H42: =(Assumptions!$C$25-H18)*Assumptions!$C$28 -> 0.375
A43: Term Loan B interest | B43: $mm | D43: =D24*D40 -> 31 | E43: =E24*E40 -> 28.534887 | F43: =F24*F40 -> 25.353033 | G43: =G24*G40 -> 22.320102 | H43: =H24*H40 -> 18.556056
A44: Senior notes interest | B44: $mm | D44: =D30*Assumptions!$C$34 -> 13.875 | E44: =E30*Assumptions!$C$34 -> 13.875 | F44: =F30*Assumptions!$C$34 -> 13.875 | G44: =G30*Assumptions!$C$34 -> 13.875 | H44: =H30*Assumptions!$C$34 -> 13.875
A45: Total cash interest expense | B45: $mm | D45: =SUM(D41:D44) -> 45.25 | E45: =SUM(E41:E44) -> 42.784887 | F45: =SUM(F41:F44) -> 39.603033 | G45: =SUM(G41:G44) -> 36.570102 | H45: =SUM(H41:H44) -> 32.806056
A46: Interest income on beginning cash | B46: $mm | D46: =D7*Assumptions!$C$35 -> 0.4 | E46: =E7*Assumptions!$C$35 -> 0.50356563 | F46: =F7*Assumptions!$C$35 -> 0.5784543 | G46: =G7*Assumptions!$C$35 -> 0.65222354 | H46: =H7*Assumptions!$C$35 -> 0.71945255

Sheet Balance Sheet
A1: Pro-Forma Balance Sheet
A2: ($ in millions unless stated) | Project Atlas is a FICTIONAL company; all inputs are illustrative
B4: Unit | C4: Close / LTM | D4: Year 1 | E4: Year 2 | F4: Year 3 | G4: Year 4 | H4: Year 5
A6: ASSETS
A7: Cash | B7: $mm | C7: =Transaction!$C$23 -> 20 | D7: ='Debt Schedule'!D15 -> 25.178281 | E7: ='Debt Schedule'!E15 -> 28.922715 | F7: ='Debt Schedule'!F15 -> 32.611177 | G7: ='Debt Schedule'!G15 -> 35.972627 | H7: ='Debt Schedule'!H15 -> 38.73414
A8: Net working capital | B8: $mm | C8: ='Operating Model'!C30 -> 60 | D8: ='Operating Model'!D30 -> 64.2 | E8: ='Operating Model'!E30 -> 68.694 | F8: ='Operating Model'!F30 -> 72.81564 | G8: ='Operating Model'!G30 -> 77.184578 | H8: ='Operating Model'!H30 -> 81.043807
A9: Net PP&E | B9: $mm | C9: =Assumptions!$C$10 -> 200 | D9: =C9+'Operating Model'!D32-'Operating Model'!D11 -> 202.675 | E9: =D9+'Operating Model'!E32-'Operating Model'!E11 -> 205.53725 | F9: =E9+'Operating Model'!F32-'Operating Model'!F11 -> 208.57124 | G9: =F9+'Operating Model'!G32-'Operating Model'!G11 -> 211.78726 | H9: =G9+'Operating Model'!H32-'Operating Model'!H11 -> 215.16408
A10: Goodwill & intangibles | B10: $mm | C10: =Transaction!$C$29 -> 862 | D10: =C10 -> 862 | E10: =D10 -> 862 | F10: =E10 -> 862 | G10: =F10 -> 862 | H10: =G10 -> 862
A11: Capitalised financing fees | B11: $mm | C11: =Transaction!$C$22 -> 15.625 | D11: =C11-'Operating Model'!D15 -> 13.392857 | E11: =D11-'Operating Model'!E15 -> 11.160714 | F11: =E11-'Operating Model'!F15 -> 8.9285714 | G11: =F11-'Operating Model'!G15 -> 6.6964286 | H11: =G11-'Operating Model'!H15 -> 4.4642857
A12: Total assets | C12: =SUM(C7:C11) -> 1157.625 | D12: =SUM(D7:D11) -> 1167.4461 | E12: =SUM(E7:E11) -> 1176.3147 | F12: =SUM(F7:F11) -> 1184.9266 | G12: =SUM(G7:G11) -> 1193.6409 | H12: =SUM(H7:H11) -> 1201.4063
A14: LIABILITIES & EQUITY
A15: Revolver | B15: $mm | C15: ='Debt Schedule'!C20 -> 0 | D15: ='Debt Schedule'!D20 -> 0 | E15: ='Debt Schedule'!E20 -> 0 | F15: ='Debt Schedule'!F20 -> 0 | G15: ='Debt Schedule'!G20 -> 0 | H15: ='Debt Schedule'!H20 -> 0
A16: Term Loan B | B16: $mm | C16: ='Debt Schedule'!C27 -> 400 | D16: ='Debt Schedule'!D27 -> 380.46516 | E16: ='Debt Schedule'!E27 -> 349.69701 | F16: ='Debt Schedule'!F27 -> 307.86348 | G16: ='Debt Schedule'!G27 -> 255.9456 | H16: ='Debt Schedule'!H27 -> 195.74318
A17: Senior unsecured notes | B17: $mm | C17: ='Debt Schedule'!C31 -> 150 | D17: ='Debt Schedule'!D31 -> 150 | E17: ='Debt Schedule'!E31 -> 150 | F17: ='Debt Schedule'!F31 -> 150 | G17: ='Debt Schedule'!G31 -> 150 | H17: ='Debt Schedule'!H31 -> 150
A18: Total debt | C18: =SUM(C15:C17) -> 550 | D18: =SUM(D15:D17) -> 530.46516 | E18: =SUM(E15:E17) -> 499.69701 | F18: =SUM(F15:F17) -> 457.86348 | G18: =SUM(G15:G17) -> 405.9456 | H18: =SUM(H15:H17) -> 345.74318
A19: Sponsor equity contributed | B19: $mm | C19: =Transaction!$C$16 -> 607.625 | D19: =C19 -> 607.625 | E19: =D19 -> 607.625 | F19: =E19 -> 607.625 | G19: =F19 -> 607.625 | H19: =G19 -> 607.625
A20: Retained earnings | B20: $mm | C20: 0 | D20: =C20+'Operating Model'!D24 -> 29.355982 | E20: =D20+'Operating Model'!E24 -> 68.992668 | F20: =E20+'Operating Model'!F24 -> 119.43814 | G20: =F20+'Operating Model'!G24 -> 180.0703 | H20: =G20+'Operating Model'!H24 -> 248.03814
A21: Total equity | C21: =C19+C20 -> 607.625 | D21: =D19+D20 -> 636.98098 | E21: =E19+E20 -> 676.61767 | F21: =F19+F20 -> 727.06314 | G21: =G19+G20 -> 787.6953 | H21: =H19+H20 -> 855.66314
A22: Total liabilities & equity | C22: =C18+C21 -> 1157.625 | D22: =D18+D21 -> 1167.4461 | E22: =E18+E21 -> 1176.3147 | F22: =F18+F21 -> 1184.9266 | G22: =G18+G21 -> 1193.6409 | H22: =H18+H21 -> 1201.4063
A24: Balance check (assets - liabilities & equity) | C24: =ROUND(C12-C22,6) -> 0 | D24: =ROUND(D12-D22,6) -> 0 | E24: =ROUND(E12-E22,6) -> 0 | F24: =ROUND(F12-F22,6) -> 0 | G24: =ROUND(G12-G22,6) -> 0 | H24: =ROUND(H12-H22,6) -> 0

Sheet Returns
A1: Returns Analysis
A2: ($ in millions unless stated) | Project Atlas is a FICTIONAL company; all inputs are illustrative
B4: Unit | C4: Close / LTM | D4: Year 1 | E4: Year 2 | F4: Year 3 | G4: Year 4 | H4: Year 5
A6: RETURNS BY EXIT YEAR (exit at the Exit Multiple on that year's EBITDA)
A7: Exit year | D7: 1 | E7: 2 | F7: 3 | G7: 4 | H7: 5
A8: EBITDA at exit | B8: $mm | D8: ='Operating Model'!D9 -> 109.675 | E8: ='Operating Model'!E9 -> 120.2145 | F8: ='Operating Model'!F9 -> 130.46135 | G8: ='Operating Model'!G9 -> 141.50506 | H8: ='Operating Model'!H9 -> 148.58031
A9: Enterprise value at exit | B9: $mm | D9: =Assumptions!$C$21*D8 -> 1206.425 | E9: =Assumptions!$C$21*E8 -> 1322.3595 | F9: =Assumptions!$C$21*F8 -> 1435.0749 | G9: =Assumptions!$C$21*G8 -> 1556.5557 | H9: =Assumptions!$C$21*H8 -> 1634.3834
A10: Less: net debt at exit | B10: $mm | D10: ='Debt Schedule'!D35 -> 505.28688 | E10: ='Debt Schedule'!E35 -> 470.7743 | F10: ='Debt Schedule'!F35 -> 425.2523 | G10: ='Debt Schedule'!G35 -> 369.97297 | H10: ='Debt Schedule'!H35 -> 307.00904
A11: Equity value at exit (100%) | B11: $mm | D11: =D9-D10 -> 701.13812 | E11: =E9-E10 -> 851.5852 | F11: =F9-F10 -> 1009.8226 | G11: =G9-G10 -> 1186.5827 | H11: =H9-H10 -> 1327.3744
A12: Sponsor equity invested at close | B12: $mm | D12: =Transaction!$C$16 -> 607.625 | E12: =Transaction!$C$16 -> 607.625 | F12: =Transaction!$C$16 -> 607.625 | G12: =Transaction!$C$16 -> 607.625 | H12: =Transaction!$C$16 -> 607.625
A13: Equity gain | B13: $mm | D13: =D11-D12 -> 93.513125 | E13: =E11-E12 -> 243.9602 | F13: =F11-F12 -> 402.1976 | G13: =G11-G12 -> 578.95769 | H13: =H11-H12 -> 719.74941
A14: Less: management incentive plan | B14: $mm | D14: =Assumptions!$C$22*MAX(0,D13) -> 7.48105 | E14: =Assumptions!$C$22*MAX(0,E13) -> 19.516816 | F14: =Assumptions!$C$22*MAX(0,F13) -> 32.175808 | G14: =Assumptions!$C$22*MAX(0,G13) -> 46.316616 | H14: =Assumptions!$C$22*MAX(0,H13) -> 57.579953
A15: Sponsor proceeds | B15: $mm | D15: =D11-D14 -> 693.65707 | E15: =E11-E14 -> 832.06839 | F15: =F11-F14 -> 977.64679 | G15: =G11-G14 -> 1140.2661 | H15: =H11-H14 -> 1269.7945
A16: MOIC | B16: x | D16: =D15/D12 -> 1.1415875 | E16: =E15/E12 -> 1.3693781 | F16: =F15/F12 -> 1.6089641 | G16: =G15/G12 -> 1.8765951 | H16: =H15/H12 -> 2.0897666
A17: IRR | B17: % | D17: =IF(D15>0,(D15/D12)^(1/D7)-1,-1) -> 0.14158745 | E17: =IF(E15>0,(E15/E12)^(1/E7)-1,-1) -> 0.17020431 | F17: =IF(F15>0,(F15/F12)^(1/F7)-1,-1) -> 0.17178729 | G17: =IF(G15>0,(G15/G12)^(1/G7)-1,-1) -> 0.17042245 | H17: =IF(H15>0,(H15/H12)^(1/H7)-1,-1) -> 0.15882954
A19: SELECTED EXIT YEAR
A20: Exit year selected | C20: =Assumptions!$C$20 -> 5
A21: Sponsor proceeds | C21: =INDEX($D15:$H15,C20) -> 1269.7945
A22: MOIC | C22: =INDEX($D16:$H16,C20) -> 2.0897666
A23: IRR | C23: =INDEX($D17:$H17,C20) -> 0.15882954
A24: Sponsor cash flows (for IRR function) | C24: =-Transaction!$C$16 -> -607.625 | D24: =IF(D7=$C20,D15,0) -> 0 | E24: =IF(E7=$C20,E15,0) -> 0 | F24: =IF(F7=$C20,F15,0) -> 0 | G24: =IF(G7=$C20,G15,0) -> 0 | H24: =IF(H7=$C20,H15,0) -> 1269.7945
A25: IRR via Excel IRR() function (cross-check) | C25: =IRR(C24:H24,0.1) -> 0.15882954
A27: VALUE CREATION BRIDGE (selected exit year) | D27: % of gain
A28: Revenue growth (at entry margin and multiple) | C28: =(INDEX('Operating Model'!$D7:$H7,$C20)-Assumptions!$C$8)*(Assumptions!$C$9/Assumptions!$C$8)*Assumptions!$C$13 -> 385.80313 | D28: =IF($C34=0,0,C28/$C34) -> 0.58263505
A29: Margin expansion (at entry multiple) | C29: =((INDEX('Operating Model'!$D9:$H9,$C20)/INDEX('Operating Model'!$D7:$H7,$C20))-(Assumptions!$C$9/Assumptions!$C$8))*INDEX('Operating Model'!$D7:$H7,$C20)*Assumptions!$C$13 -> 148.58031 | D29: =IF($C34=0,0,C29/$C34) -> 0.22438412
A30: Multiple expansion / (contraction) | C30: =(Assumptions!$C$21-Assumptions!$C$13)*INDEX('Operating Model'!$D9:$H9,$C20) -> 0 | D30: =IF($C34=0,0,C30/$C34) -> 0
A31: Deleveraging (net debt reduction) | C31: ='Debt Schedule'!C35-INDEX('Debt Schedule'!$D35:$H35,$C20) -> 222.99096 | D31: =IF($C34=0,0,C31/$C34) -> 0.33675815
A32: Fees and expenses | C32: =-(Transaction!$C$21+Transaction!$C$22) -> -37.625 | D32: =IF($C34=0,0,C32/$C34) -> -0.056820803
A33: Management incentive plan | C33: =-INDEX($D14:$H14,C20) -> -57.579953 | D33: =IF($C34=0,0,C33/$C34) -> -0.086956522
A34: Total sponsor gain | C34: =SUM(C28:C33) -> 662.16946 | D34: =IF($C34=0,0,C34/$C34) -> 1
A35: Check vs. proceeds less equity invested | C35: =ROUND(C34-(C21-Transaction!$C$16),6) -> 0

Sheet Credit Stats
A1: Credit Statistics & Covenant Headroom
A2: ($ in millions unless stated) | Project Atlas is a FICTIONAL company; all inputs are illustrative
B4: Unit | C4: Close / LTM | D4: Year 1 | E4: Year 2 | F4: Year 3 | G4: Year 4 | H4: Year 5
A6: LEVERAGE
A7: Total debt / EBITDA | C7: =IFERROR('Debt Schedule'!C34/'Operating Model'!C9,0) -> 5.5 | D7: =IFERROR('Debt Schedule'!D34/'Operating Model'!D9,0) -> 4.8367008 | E7: =IFERROR('Debt Schedule'!E34/'Operating Model'!E9,0) -> 4.1567116 | F7: =IFERROR('Debt Schedule'!F34/'Operating Model'!F9,0) -> 3.5095717 | G7: =IFERROR('Debt Schedule'!G34/'Operating Model'!G9,0) -> 2.8687709 | H7: =IFERROR('Debt Schedule'!H34/'Operating Model'!H9,0) -> 2.3269784
A8: Net debt / EBITDA | C8: =IFERROR('Debt Schedule'!C35/'Operating Model'!C9,0) -> 5.3 | D8: =IFERROR('Debt Schedule'!D35/'Operating Model'!D9,0) -> 4.607129 | E8: =IFERROR('Debt Schedule'!E35/'Operating Model'!E9,0) -> 3.9161191 | F8: =IFERROR('Debt Schedule'!F35/'Operating Model'!F9,0) -> 3.2596036 | G8: =IFERROR('Debt Schedule'!G35/'Operating Model'!G9,0) -> 2.6145565 | H8: =IFERROR('Debt Schedule'!H35/'Operating Model'!H9,0) -> 2.0662834
A9: Senior secured debt / EBITDA | C9: =IFERROR(('Debt Schedule'!C20+'Debt Schedule'!C27)/'Operating Model'!C9,0) -> 4 | D9: =IFERROR(('Debt Schedule'!D20+'Debt Schedule'!D27)/'Operating Model'!D9,0) -> 3.4690235 | E9: =IFERROR(('Debt Schedule'!E20+'Debt Schedule'!E27)/'Operating Model'!E9,0) -> 2.908942 | F9: =IFERROR(('Debt Schedule'!F20+'Debt Schedule'!F27)/'Operating Model'!F9,0) -> 2.3598059 | G9: =IFERROR(('Debt Schedule'!G20+'Debt Schedule'!G27)/'Operating Model'!G9,0) -> 1.8087381 | H9: =IFERROR(('Debt Schedule'!H20+'Debt Schedule'!H27)/'Operating Model'!H9,0) -> 1.3174234
A11: COVERAGE
A12: EBITDA / cash interest | B12: x | D12: =IFERROR('Operating Model'!D9/'Debt Schedule'!D45,0) -> 2.4237569 | E12: =IFERROR('Operating Model'!E9/'Debt Schedule'!E45,0) -> 2.8097422 | F12: =IFERROR('Operating Model'!F9/'Debt Schedule'!F45,0) -> 3.2942263 | G12: =IFERROR('Operating Model'!G9/'Debt Schedule'!G45,0) -> 3.8694193 | H12: =IFERROR('Operating Model'!H9/'Debt Schedule'!H45,0) -> 4.5290514
A13: (EBITDA - capex) / cash interest | B13: x | D13: =IFERROR(('Operating Model'!D9-'Operating Model'!D32)/'Debt Schedule'!D45,0) -> 1.9508287 | E13: =IFERROR(('Operating Model'!E9-'Operating Model'!E32)/'Debt Schedule'!E45,0) -> 2.2745532 | F13: =IFERROR(('Operating Model'!F9-'Operating Model'!F32)/'Debt Schedule'!F45,0) -> 2.681347 | G13: =IFERROR(('Operating Model'!G9-'Operating Model'!G32)/'Debt Schedule'!G45,0) -> 3.1658885 | H13: =IFERROR(('Operating Model'!H9-'Operating Model'!H32)/'Debt Schedule'!H45,0) -> 3.7055875
A14: Fixed-charge coverage: (EBITDA - capex - taxes) / (interest + mandatory amortisation) | B14: x | D14: =IFERROR(('Operating Model'!D9-'Operating Model'!D32-'Operating Model'!D23)/('Debt Schedule'!D45+'Debt Schedule'!D25),0) -> 1.4977284 | E14: =IFERROR(('Operating Model'!E9-'Operating Model'!E32-'Operating Model'!E23)/('Debt Schedule'!E45+'Debt Schedule'!E25),0) -> 1.737482 | F14: =IFERROR(('Operating Model'!F9-'Operating Model'!F32-'Operating Model'!F23)/('Debt Schedule'!F45+'Debt Schedule'!F25),0) -> 2.0335331 | G14: =IFERROR(('Operating Model'!G9-'Operating Model'!G32-'Operating Model'!G23)/('Debt Schedule'!G45+'Debt Schedule'!G25),0) -> 2.3555807 | H14: =IFERROR(('Operating Model'!H9-'Operating Model'!H32-'Operating Model'!H23)/('Debt Schedule'!H45+'Debt Schedule'!H25),0) -> 2.6873231
A16: DELEVERAGING
A17: FCF / total debt | B17: % | D17: =IFERROR('Operating Model'!D33/'Debt Schedule'!D34,0) -> 0.04658765 | E17: =IFERROR('Operating Model'!E33/'Debt Schedule'!E34,0) -> 0.069067011 | F17: =IFERROR('Operating Model'!F33/'Debt Schedule'!F34,0) -> 0.099422633 | G17: =IFERROR('Operating Model'!G33/'Debt Schedule'!G34,0) -> 0.13617424 | H17: =IFERROR('Operating Model'!H33/'Debt Schedule'!H34,0) -> 0.18211185
A18: Cumulative debt paydown (% of debt at close) | B18: % | D18: =1-'Debt Schedule'!D34/'Debt Schedule'!C34 -> 0.035517898 | E18: =1-'Debt Schedule'!E34/'Debt Schedule'!C34 -> 0.09145998 | F18: =1-'Debt Schedule'!F34/'Debt Schedule'!C34 -> 0.16752094 | G18: =1-'Debt Schedule'!G34/'Debt Schedule'!C34 -> 0.26191709 | H18: =1-'Debt Schedule'!H34/'Debt Schedule'!C34 -> 0.37137604
A20: COVENANT (maximum net leverage)
A21: Covenant level | B21: x | D21: =Assumptions!D47 -> 7 | E21: =Assumptions!E47 -> 6.75 | F21: =Assumptions!F47 -> 6.5 | G21: =Assumptions!G47 -> 6.25 | H21: =Assumptions!H47 -> 6
A22: Leverage headroom (% below covenant) | B22: % | D22: =1-D8/D21 -> 0.34183871 | E22: =1-E8/E21 -> 0.41983421 | F22: =1-F8/F21 -> 0.49852252 | G22: =1-G8/G21 -> 0.58167097 | H22: =1-H8/H21 -> 0.65561943
A23: EBITDA cushion (% EBITDA can fall before breach) | B23: % | D23: =1-('Debt Schedule'!D35/D21)/'Operating Model'!D9 -> 0.34183871 | E23: =1-('Debt Schedule'!E35/E21)/'Operating Model'!E9 -> 0.41983421 | F23: =1-('Debt Schedule'!F35/F21)/'Operating Model'!F9 -> 0.49852252 | G23: =1-('Debt Schedule'!G35/G21)/'Operating Model'!G9 -> 0.58167097 | H23: =1-('Debt Schedule'!H35/H21)/'Operating Model'!H9 -> 0.65561943
A24: Covenant status | D24: =IF(D8>D21,"BREACH","OK") -> OK | E24: =IF(E8>E21,"BREACH","OK") -> OK | F24: =IF(F8>F21,"BREACH","OK") -> OK | G24: =IF(G8>G21,"BREACH","OK") -> OK | H24: =IF(H8>H21,"BREACH","OK") -> OK

Sheet Sensitivity
A1: Sensitivity Analysis
A2: Tables 1-3 are LIVE closed-form formulas (debt schedule is independent of entry/exit multiple). Tables 4-5 are STATIC snapshots from the Python engine.
B4: Live helper cells
B5: Exit year (N) | C5: =Assumptions!$C$20 -> 5
B6: EBITDA at exit | C6: =INDEX('Operating Model'!$D9:$H9,Assumptions!$C$20) -> 148.58031
B7: Net debt at exit | C7: =INDEX('Debt Schedule'!$D35:$H35,Assumptions!$C$20) -> 307.00904
B8: LTM EBITDA | C8: =Assumptions!$C$9 -> 100
B9: Funded debt at close | C9: =SUM(Transaction!$C$13:$C$15) -> 550
B10: Financing fees | C10: =Transaction!$C$22 -> 15.625
B11: Minimum cash funded | C11: =Transaction!$C$23 -> 20
B12: Transaction fee % | C12: =Assumptions!$C$14 -> 0.02
B13: MIP % | C13: =Assumptions!$C$22 -> 0.08
B14: Base entry multiple | C14: =Assumptions!$C$13 -> 11
B15: Base exit multiple | C15: =Assumptions!$C$21 -> 11
B16: Sponsor equity at close | C16: =Transaction!$C$16 -> 607.625
B17: Entry multiple step (x) | C17: 0.5
B18: Exit multiple step (x) | C18: 1
B21: Table 1: Sponsor IRR, entry multiple (rows) vs exit multiple (columns), selected exit year
B22: Entry \ Exit | C22: =$C$15+-2*$C$18 -> 9 | D22: =$C$15+-1*$C$18 -> 10 | E22: =$C$15+0*$C$18 -> 11 | F22: =$C$15+1*$C$18 -> 12 | G22: =$C$15+2*$C$18 -> 13
B23: =$C$14+-3*$C$17 -> 9.5 | C23: =IF(AND(((C$22*$C$6-$C$7)-$C$13*MAX(0,(C$22*$C$6-$C$7)-($B23*$C$8*(1+$C$12)+$C$10+$C$11-$C$9)))>0,($B23*$C$8*(1+$C$12)+$C$10+$C$11-$C$9)>0),(((C$22*$C$6-$C$7)-$C$13*MAX(0,(C$22*$C$6-$C$7)-($B23*$C$8*(1+$C$12)+$C$10+$C$11-$C$9)))/($B23*$C$8*(1+$C$12)+$C$10+$C$11-$C$9))^(1/$C$5)-1,-1) -> 0.16703282 | D23: =IF(AND(((D$22*$C$6-$C$7)-$C$13*MAX(0,(D$22*$C$6-$C$7)-($B23*$C$8*(1+$C$12)+$C$10+$C$11-$C$9)))>0,($B23*$C$8*(1+$C$12)+$C$10+$C$11-$C$9)>0),(((D$22*$C$6-$C$7)-$C$13*MAX(0,(D$22*$C$6-$C$7)-($B23*$C$8*(1+$C$12)+$C$10+$C$11-$C$9)))/($B23*$C$8*(1+$C$12)+$C$10+$C$11-$C$9))^(1/$C$5)-1,-1) -> 0.19778717 | E23: =IF(AND(((E$22*$C$6-$C$7)-$C$13*MAX(0,(E$22*$C$6-$C$7)-($B23*$C$8*(1+$C$12)+$C$10+$C$11-$C$9)))>0,($B23*$C$8*(1+$C$12)+$C$10+$C$11-$C$9)>0),(((E$22*$C$6-$C$7)-$C$13*MAX(0,(E$22*$C$6-$C$7)-($B23*$C$8*(1+$C$12)+$C$10+$C$11-$C$9)))/($B23*$C$8*(1+$C$12)+$C$10+$C$11-$C$9))^(1/$C$5)-1,-1) -> 0.22567322 | F23: =IF(AND(((F$22*$C$6-$C$7)-$C$13*MAX(0,(F$22*$C$6-$C$7)-($B23*$C$8*(1+$C$12)+$C$10+$C$11-$C$9)))>0,($B23*$C$8*(1+$C$12)+$C$10+$C$11-$C$9)>0),(((F$22*$C$6-$C$7)-$C$13*MAX(0,(F$22*$C$6-$C$7)-($B23*$C$8*(1+$C$12)+$C$10+$C$11-$C$9)))/($B23*$C$8*(1+$C$12)+$C$10+$C$11-$C$9))^(1/$C$5)-1,-1) -> 0.25123062 | G23: =IF(AND(((G$22*$C$6-$C$7)-$C$13*MAX(0,(G$22*$C$6-$C$7)-($B23*$C$8*(1+$C$12)+$C$10+$C$11-$C$9)))>0,($B23*$C$8*(1+$C$12)+$C$10+$C$11-$C$9)>0),(((G$22*$C$6-$C$7)-$C$13*MAX(0,(G$22*$C$6-$C$7)-($B23*$C$8*(1+$C$12)+$C$10+$C$11-$C$9)))/($B23*$C$8*(1+$C$12)+$C$10+$C$11-$C$9))^(1/$C$5)-1,-1) -> 0.2748559
B24: =$C$14+-2*$C$17 -> 10 | C24: =IF(AND(((C$22*$C$6-$C$7)-$C$13*MAX(0,(C$22*$C$6-$C$7)-($B24*$C$8*(1+$C$12)+$C$10+$C$11-$C$9)))>0,($B24*$C$8*(1+$C$12)+$C$10+$C$11-$C$9)>0),(((C$22*$C$6-$C$7)-$C$13*MAX(0,(C$22*$C$6-$C$7)-($B24*$C$8*(1+$C$12)+$C$10+$C$11-$C$9)))/($B24*$C$8*(1+$C$12)+$C$10+$C$11-$C$9))^(1/$C$5)-1,-1) -> 0.14342416 | D24: =IF(AND(((D$22*$C$6-$C$7)-$C$13*MAX(0,(D$22*$C$6-$C$7)-($B24*$C$8*(1+$C$12)+$C$10+$C$11-$C$9)))>0,($B24*$C$8*(1+$C$12)+$C$10+$C$11-$C$9)>0),(((D$22*$C$6-$C$7)-$C$13*MAX(0,(D$22*$C$6-$C$7)-($B24*$C$8*(1+$C$12)+$C$10+$C$11-$C$9)))/($B24*$C$8*(1+$C$12)+$C$10+$C$11-$C$9))^(1/$C$5)-1,-1) -> 0.17343816 | E24: =IF(AND(((E$22*$C$6-$C$7)-$C$13*MAX(0,(E$22*$C$6-$C$7)-($B24*$C$8*(1+$C$12)+$C$10+$C$11-$C$9)))>0,($B24*$C$8*(1+$C$12)+$C$10+$C$11-$C$9)>0),(((E$22*$C$6-$C$7)-$C$13*MAX(0,(E$22*$C$6-$C$7)-($B24*$C$8*(1+$C$12)+$C$10+$C$11-$C$9)))/($B24*$C$8*(1+$C$12)+$C$10+$C$11-$C$9))^(1/$C$5)-1,-1) -> 0.20066265 | F24: =IF(AND(((F$22*$C$6-$C$7)-$C$13*MAX(0,(F$22*$C$6-$C$7)-($B24*$C$8*(1+$C$12)+$C$10+$C$11-$C$9)))>0,($B24*$C$8*(1+$C$12)+$C$10+$C$11-$C$9)>0),(((F$22*$C$6-$C$7)-$C$13*MAX(0,(F$22*$C$6-$C$7)-($B24*$C$8*(1+$C$12)+$C$10+$C$11-$C$9)))/($B24*$C$8*(1+$C$12)+$C$10+$C$11-$C$9))^(1/$C$5)-1,-1) -> 0.2256208 | G24: =IF(AND(((G$22*$C$6-$C$7)-$C$13*MAX(0,(G$22*$C$6-$C$7)-($B24*$C$8*(1+$C$12)+$C$10+$C$11-$C$9)))>0,($B24*$C$8*(1+$C$12)+$C$10+$C$11-$C$9)>0),(((G$22*$C$6-$C$7)-$C$13*MAX(0,(G$22*$C$6-$C$7)-($B24*$C$8*(1+$C$12)+$C$10+$C$11-$C$9)))/($B24*$C$8*(1+$C$12)+$C$10+$C$11-$C$9))^(1/$C$5)-1,-1) -> 0.24869745
B25: =$C$14+-1*$C$17 -> 10.5 | C25: =IF(AND(((C$22*$C$6-$C$7)-$C$13*MAX(0,(C$22*$C$6-$C$7)-($B25*$C$8*(1+$C$12)+$C$10+$C$11-$C$9)))>0,($B25*$C$8*(1+$C$12)+$C$10+$C$11-$C$9)>0),(((C$22*$C$6-$C$7)-$C$13*MAX(0,(C$22*$C$6-$C$7)-($B25*$C$8*(1+$C$12)+$C$10+$C$11-$C$9)))/($B25*$C$8*(1+$C$12)+$C$10+$C$11-$C$9))^(1/$C$5)-1,-1) -> 0.12258282 | D25: =IF(AND(((D$22*$C$6-$C$7)-$C$13*MAX(0,(D$22*$C$6-$C$7)-($B25*$C$8*(1+$C$12)+$C$10+$C$11-$C$9)))>0,($B25*$C$8*(1+$C$12)+$C$10+$C$11-$C$9)>0),(((D$22*$C$6-$C$7)-$C$13*MAX(0,(D$22*$C$6-$C$7)-($B25*$C$8*(1+$C$12)+$C$10+$C$11-$C$9)))/($B25*$C$8*(1+$C$12)+$C$10+$C$11-$C$9))^(1/$C$5)-1,-1) -> 0.15193462 | E25: =IF(AND(((E$22*$C$6-$C$7)-$C$13*MAX(0,(E$22*$C$6-$C$7)-($B25*$C$8*(1+$C$12)+$C$10+$C$11-$C$9)))>0,($B25*$C$8*(1+$C$12)+$C$10+$C$11-$C$9)>0),(((E$22*$C$6-$C$7)-$C$13*MAX(0,(E$22*$C$6-$C$7)-($B25*$C$8*(1+$C$12)+$C$10+$C$11-$C$9)))/($B25*$C$8*(1+$C$12)+$C$10+$C$11-$C$9))^(1/$C$5)-1,-1) -> 0.17856789 | F25: =IF(AND(((F$22*$C$6-$C$7)-$C$13*MAX(0,(F$22*$C$6-$C$7)-($B25*$C$8*(1+$C$12)+$C$10+$C$11-$C$9)))>0,($B25*$C$8*(1+$C$12)+$C$10+$C$11-$C$9)>0),(((F$22*$C$6-$C$7)-$C$13*MAX(0,(F$22*$C$6-$C$7)-($B25*$C$8*(1+$C$12)+$C$10+$C$11-$C$9)))/($B25*$C$8*(1+$C$12)+$C$10+$C$11-$C$9))^(1/$C$5)-1,-1) -> 0.20299094 | G25: =IF(AND(((G$22*$C$6-$C$7)-$C$13*MAX(0,(G$22*$C$6-$C$7)-($B25*$C$8*(1+$C$12)+$C$10+$C$11-$C$9)))>0,($B25*$C$8*(1+$C$12)+$C$10+$C$11-$C$9)>0),(((G$22*$C$6-$C$7)-$C$13*MAX(0,(G$22*$C$6-$C$7)-($B25*$C$8*(1+$C$12)+$C$10+$C$11-$C$9)))/($B25*$C$8*(1+$C$12)+$C$10+$C$11-$C$9))^(1/$C$5)-1,-1) -> 0.22557799
B26: =$C$14+0*$C$17 -> 11 | C26: =IF(AND(((C$22*$C$6-$C$7)-$C$13*MAX(0,(C$22*$C$6-$C$7)-($B26*$C$8*(1+$C$12)+$C$10+$C$11-$C$9)))>0,($B26*$C$8*(1+$C$12)+$C$10+$C$11-$C$9)>0),(((C$22*$C$6-$C$7)-$C$13*MAX(0,(C$22*$C$6-$C$7)-($B26*$C$8*(1+$C$12)+$C$10+$C$11-$C$9)))/($B26*$C$8*(1+$C$12)+$C$10+$C$11-$C$9))^(1/$C$5)-1,-1) -> 0.10397744 | D26: =IF(AND(((D$22*$C$6-$C$7)-$C$13*MAX(0,(D$22*$C$6-$C$7)-($B26*$C$8*(1+$C$12)+$C$10+$C$11-$C$9)))>0,($B26*$C$8*(1+$C$12)+$C$10+$C$11-$C$9)>0),(((D$22*$C$6-$C$7)-$C$13*MAX(0,(D$22*$C$6-$C$7)-($B26*$C$8*(1+$C$12)+$C$10+$C$11-$C$9)))/($B26*$C$8*(1+$C$12)+$C$10+$C$11-$C$9))^(1/$C$5)-1,-1) -> 0.13273042 | E26: =IF(AND(((E$22*$C$6-$C$7)-$C$13*MAX(0,(E$22*$C$6-$C$7)-($B26*$C$8*(1+$C$12)+$C$10+$C$11-$C$9)))>0,($B26*$C$8*(1+$C$12)+$C$10+$C$11-$C$9)>0),(((E$22*$C$6-$C$7)-$C$13*MAX(0,(E$22*$C$6-$C$7)-($B26*$C$8*(1+$C$12)+$C$10+$C$11-$C$9)))/($B26*$C$8*(1+$C$12)+$C$10+$C$11-$C$9))^(1/$C$5)-1,-1) -> 0.15882954 | F26: =IF(AND(((F$22*$C$6-$C$7)-$C$13*MAX(0,(F$22*$C$6-$C$7)-($B26*$C$8*(1+$C$12)+$C$10+$C$11-$C$9)))>0,($B26*$C$8*(1+$C$12)+$C$10+$C$11-$C$9)>0),(((F$22*$C$6-$C$7)-$C$13*MAX(0,(F$22*$C$6-$C$7)-($B26*$C$8*(1+$C$12)+$C$10+$C$11-$C$9)))/($B26*$C$8*(1+$C$12)+$C$10+$C$11-$C$9))^(1/$C$5)-1,-1) -> 0.18276946 | G26: =IF(AND(((G$22*$C$6-$C$7)-$C$13*MAX(0,(G$22*$C$6-$C$7)-($B26*$C$8*(1+$C$12)+$C$10+$C$11-$C$9)))>0,($B26*$C$8*(1+$C$12)+$C$10+$C$11-$C$9)>0),(((G$22*$C$6-$C$7)-$C$13*MAX(0,(G$22*$C$6-$C$7)-($B26*$C$8*(1+$C$12)+$C$10+$C$11-$C$9)))/($B26*$C$8*(1+$C$12)+$C$10+$C$11-$C$9))^(1/$C$5)-1,-1) -> 0.20491474
B27: =$C$14+1*$C$17 -> 11.5 | C27: =IF(AND(((C$22*$C$6-$C$7)-$C$13*MAX(0,(C$22*$C$6-$C$7)-($B27*$C$8*(1+$C$12)+$C$10+$C$11-$C$9)))>0,($B27*$C$8*(1+$C$12)+$C$10+$C$11-$C$9)>0),(((C$22*$C$6-$C$7)-$C$13*MAX(0,(C$22*$C$6-$C$7)-($B27*$C$8*(1+$C$12)+$C$10+$C$11-$C$9)))/($B27*$C$8*(1+$C$12)+$C$10+$C$11-$C$9))^(1/$C$5)-1,-1) -> 0.087212958 | D27: =IF(AND(((D$22*$C$6-$C$7)-$C$13*MAX(0,(D$22*$C$6-$C$7)-($B27*$C$8*(1+$C$12)+$C$10+$C$11-$C$9)))>0,($B27*$C$8*(1+$C$12)+$C$10+$C$11-$C$9)>0),(((D$22*$C$6-$C$7)-$C$13*MAX(0,(D$22*$C$6-$C$7)-($B27*$C$8*(1+$C$12)+$C$10+$C$11-$C$9)))/($B27*$C$8*(1+$C$12)+$C$10+$C$11-$C$9))^(1/$C$5)-1,-1) -> 0.11541953 | E27: =IF(AND(((E$22*$C$6-$C$7)-$C$13*MAX(0,(E$22*$C$6-$C$7)-($B27*$C$8*(1+$C$12)+$C$10+$C$11-$C$9)))>0,($B27*$C$8*(1+$C$12)+$C$10+$C$11-$C$9)>0),(((E$22*$C$6-$C$7)-$C$13*MAX(0,(E$22*$C$6-$C$7)-($B27*$C$8*(1+$C$12)+$C$10+$C$11-$C$9)))/($B27*$C$8*(1+$C$12)+$C$10+$C$11-$C$9))^(1/$C$5)-1,-1) -> 0.14103163 | F27: =IF(AND(((F$22*$C$6-$C$7)-$C$13*MAX(0,(F$22*$C$6-$C$7)-($B27*$C$8*(1+$C$12)+$C$10+$C$11-$C$9)))>0,($B27*$C$8*(1+$C$12)+$C$10+$C$11-$C$9)>0),(((F$22*$C$6-$C$7)-$C$13*MAX(0,(F$22*$C$6-$C$7)-($B27*$C$8*(1+$C$12)+$C$10+$C$11-$C$9)))/($B27*$C$8*(1+$C$12)+$C$10+$C$11-$C$9))^(1/$C$5)-1,-1) -> 0.16453135 | G27: =IF(AND(((G$22*$C$6-$C$7)-$C$13*MAX(0,(G$22*$C$6-$C$7)-($B27*$C$8*(1+$C$12)+$C$10+$C$11-$C$9)))>0,($B27*$C$8*(1+$C$12)+$C$10+$C$11-$C$9)>0),(((G$22*$C$6-$C$7)-$C$13*MAX(0,(G$22*$C$6-$C$7)-($B27*$C$8*(1+$C$12)+$C$10+$C$11-$C$9)))/($B27*$C$8*(1+$C$12)+$C$10+$C$11-$C$9))^(1/$C$5)-1,-1) -> 0.18627436
B28: =$C$14+2*$C$17 -> 12 | C28: =IF(AND(((C$22*$C$6-$C$7)-$C$13*MAX(0,(C$22*$C$6-$C$7)-($B28*$C$8*(1+$C$12)+$C$10+$C$11-$C$9)))>0,($B28*$C$8*(1+$C$12)+$C$10+$C$11-$C$9)>0),(((C$22*$C$6-$C$7)-$C$13*MAX(0,(C$22*$C$6-$C$7)-($B28*$C$8*(1+$C$12)+$C$10+$C$11-$C$9)))/($B28*$C$8*(1+$C$12)+$C$10+$C$11-$C$9))^(1/$C$5)-1,-1) -> 0.07198812 | D28: =IF(AND(((D$22*$C$6-$C$7)-$C$13*MAX(0,(D$22*$C$6-$C$7)-($B28*$C$8*(1+$C$12)+$C$10+$C$11-$C$9)))>0,($B28*$C$8*(1+$C$12)+$C$10+$C$11-$C$9)>0),(((D$22*$C$6-$C$7)-$C$13*MAX(0,(D$22*$C$6-$C$7)-($B28*$C$8*(1+$C$12)+$C$10+$C$11-$C$9)))/($B28*$C$8*(1+$C$12)+$C$10+$C$11-$C$9))^(1/$C$5)-1,-1) -> 0.099692292 | E28: =IF(AND(((E$22*$C$6-$C$7)-$C$13*MAX(0,(E$22*$C$6-$C$7)-($B28*$C$8*(1+$C$12)+$C$10+$C$11-$C$9)))>0,($B28*$C$8*(1+$C$12)+$C$10+$C$11-$C$9)>0),(((E$22*$C$6-$C$7)-$C$13*MAX(0,(E$22*$C$6-$C$7)-($B28*$C$8*(1+$C$12)+$C$10+$C$11-$C$9)))/($B28*$C$8*(1+$C$12)+$C$10+$C$11-$C$9))^(1/$C$5)-1,-1) -> 0.12485694 | F28: =IF(AND(((F$22*$C$6-$C$7)-$C$13*MAX(0,(F$22*$C$6-$C$7)-($B28*$C$8*(1+$C$12)+$C$10+$C$11-$C$9)))>0,($B28*$C$8*(1+$C$12)+$C$10+$C$11-$C$9)>0),(((F$22*$C$6-$C$7)-$C$13*MAX(0,(F$22*$C$6-$C$7)-($B28*$C$8*(1+$C$12)+$C$10+$C$11-$C$9)))/($B28*$C$8*(1+$C$12)+$C$10+$C$11-$C$9))^(1/$C$5)-1,-1) -> 0.1479525 | G28: =IF(AND(((G$22*$C$6-$C$7)-$C$13*MAX(0,(G$22*$C$6-$C$7)-($B28*$C$8*(1+$C$12)+$C$10+$C$11-$C$9)))>0,($B28*$C$8*(1+$C$12)+$C$10+$C$11-$C$9)>0),(((G$22*$C$6-$C$7)-$C$13*MAX(0,(G$22*$C$6-$C$7)-($B28*$C$8*(1+$C$12)+$C$10+$C$11-$C$9)))/($B28*$C$8*(1+$C$12)+$C$10+$C$11-$C$9))^(1/$C$5)-1,-1) -> 0.16932636
B29: =$C$14+3*$C$17 -> 12.5 | C29: =IF(AND(((C$22*$C$6-$C$7)-$C$13*MAX(0,(C$22*$C$6-$C$7)-($B29*$C$8*(1+$C$12)+$C$10+$C$11-$C$9)))>0,($B29*$C$8*(1+$C$12)+$C$10+$C$11-$C$9)>0),(((C$22*$C$6-$C$7)-$C$13*MAX(0,(C$22*$C$6-$C$7)-($B29*$C$8*(1+$C$12)+$C$10+$C$11-$C$9)))/($B29*$C$8*(1+$C$12)+$C$10+$C$11-$C$9))^(1/$C$5)-1,-1) -> 0.058068277 | D29: =IF(AND(((D$22*$C$6-$C$7)-$C$13*MAX(0,(D$22*$C$6-$C$7)-($B29*$C$8*(1+$C$12)+$C$10+$C$11-$C$9)))>0,($B29*$C$8*(1+$C$12)+$C$10+$C$11-$C$9)>0),(((D$22*$C$6-$C$7)-$C$13*MAX(0,(D$22*$C$6-$C$7)-($B29*$C$8*(1+$C$12)+$C$10+$C$11-$C$9)))/($B29*$C$8*(1+$C$12)+$C$10+$C$11-$C$9))^(1/$C$5)-1,-1) -> 0.085307513 | E29: =IF(AND(((E$22*$C$6-$C$7)-$C$13*MAX(0,(E$22*$C$6-$C$7)-($B29*$C$8*(1+$C$12)+$C$10+$C$11-$C$9)))>0,($B29*$C$8*(1+$C$12)+$C$10+$C$11-$C$9)>0),(((E$22*$C$6-$C$7)-$C$13*MAX(0,(E$22*$C$6-$C$7)-($B29*$C$8*(1+$C$12)+$C$10+$C$11-$C$9)))/($B29*$C$8*(1+$C$12)+$C$10+$C$11-$C$9))^(1/$C$5)-1,-1) -> 0.11005838 | F29: =IF(AND(((F$22*$C$6-$C$7)-$C$13*MAX(0,(F$22*$C$6-$C$7)-($B29*$C$8*(1+$C$12)+$C$10+$C$11-$C$9)))>0,($B29*$C$8*(1+$C$12)+$C$10+$C$11-$C$9)>0),(((F$22*$C$6-$C$7)-$C$13*MAX(0,(F$22*$C$6-$C$7)-($B29*$C$8*(1+$C$12)+$C$10+$C$11-$C$9)))/($B29*$C$8*(1+$C$12)+$C$10+$C$11-$C$9))^(1/$C$5)-1,-1) -> 0.13278041 | G29: =IF(AND(((G$22*$C$6-$C$7)-$C$13*MAX(0,(G$22*$C$6-$C$7)-($B29*$C$8*(1+$C$12)+$C$10+$C$11-$C$9)))>0,($B29*$C$8*(1+$C$12)+$C$10+$C$11-$C$9)>0),(((G$22*$C$6-$C$7)-$C$13*MAX(0,(G$22*$C$6-$C$7)-($B29*$C$8*(1+$C$12)+$C$10+$C$11-$C$9)))/($B29*$C$8*(1+$C$12)+$C$10+$C$11-$C$9))^(1/$C$5)-1,-1) -> 0.1538133
B32: Table 2: Sponsor MOIC, entry multiple vs exit multiple
B33: Entry \ Exit | C33: =$C$15+-2*$C$18 -> 9 | D33: =$C$15+-1*$C$18 -> 10 | E33: =$C$15+0*$C$18 -> 11 | F33: =$C$15+1*$C$18 -> 12 | G33: =$C$15+2*$C$18 -> 13
B34: =$C$14+-3*$C$17 -> 9.5 | C34: =IFERROR(((C$33*$C$6-$C$7)-$C$13*MAX(0,(C$33*$C$6-$C$7)-($B34*$C$8*(1+$C$12)+$C$10+$C$11-$C$9)))/($B34*$C$8*(1+$C$12)+$C$10+$C$11-$C$9),0) -> 2.1647879 | D34: =IFERROR(((D$33*$C$6-$C$7)-$C$13*MAX(0,(D$33*$C$6-$C$7)-($B34*$C$8*(1+$C$12)+$C$10+$C$11-$C$9)))/($B34*$C$8*(1+$C$12)+$C$10+$C$11-$C$9),0) -> 2.4654618 | E34: =IFERROR(((E$33*$C$6-$C$7)-$C$13*MAX(0,(E$33*$C$6-$C$7)-($B34*$C$8*(1+$C$12)+$C$10+$C$11-$C$9)))/($B34*$C$8*(1+$C$12)+$C$10+$C$11-$C$9),0) -> 2.7661357 | F34: =IFERROR(((F$33*$C$6-$C$7)-$C$13*MAX(0,(F$33*$C$6-$C$7)-($B34*$C$8*(1+$C$12)+$C$10+$C$11-$C$9)))/($B34*$C$8*(1+$C$12)+$C$10+$C$11-$C$9),0) -> 3.0668097 | G34: =IFERROR(((G$33*$C$6-$C$7)-$C$13*MAX(0,(G$33*$C$6-$C$7)-($B34*$C$8*(1+$C$12)+$C$10+$C$11-$C$9)))/($B34*$C$8*(1+$C$12)+$C$10+$C$11-$C$9),0) -> 3.3674836
B35: =$C$14+-2*$C$17 -> 10 | C35: =IFERROR(((C$33*$C$6-$C$7)-$C$13*MAX(0,(C$33*$C$6-$C$7)-($B35*$C$8*(1+$C$12)+$C$10+$C$11-$C$9)))/($B35*$C$8*(1+$C$12)+$C$10+$C$11-$C$9),0) -> 1.9545052 | D35: =IFERROR(((D$33*$C$6-$C$7)-$C$13*MAX(0,(D$33*$C$6-$C$7)-($B35*$C$8*(1+$C$12)+$C$10+$C$11-$C$9)))/($B35*$C$8*(1+$C$12)+$C$10+$C$11-$C$9),0) -> 2.2248516 | E35: =IFERROR(((E$33*$C$6-$C$7)-$C$13*MAX(0,(E$33*$C$6-$C$7)-($B35*$C$8*(1+$C$12)+$C$10+$C$11-$C$9)))/($B35*$C$8*(1+$C$12)+$C$10+$C$11-$C$9),0) -> 2.4951979 | F35: =IFERROR(((F$33*$C$6-$C$7)-$C$13*MAX(0,(F$33*$C$6-$C$7)-($B35*$C$8*(1+$C$12)+$C$10+$C$11-$C$9)))/($B35*$C$8*(1+$C$12)+$C$10+$C$11-$C$9),0) -> 2.7655443 | G35: =IFERROR(((G$33*$C$6-$C$7)-$C$13*MAX(0,(G$33*$C$6-$C$7)-($B35*$C$8*(1+$C$12)+$C$10+$C$11-$C$9)))/($B35*$C$8*(1+$C$12)+$C$10+$C$11-$C$9),0) -> 3.0358907
B36: =$C$14+-1*$C$17 -> 10.5 | C36: =IFERROR(((C$33*$C$6-$C$7)-$C$13*MAX(0,(C$33*$C$6-$C$7)-($B36*$C$8*(1+$C$12)+$C$10+$C$11-$C$9)))/($B36*$C$8*(1+$C$12)+$C$10+$C$11-$C$9),0) -> 1.7827562 | D36: =IFERROR(((D$33*$C$6-$C$7)-$C$13*MAX(0,(D$33*$C$6-$C$7)-($B36*$C$8*(1+$C$12)+$C$10+$C$11-$C$9)))/($B36*$C$8*(1+$C$12)+$C$10+$C$11-$C$9),0) -> 2.0283325 | E36: =IFERROR(((E$33*$C$6-$C$7)-$C$13*MAX(0,(E$33*$C$6-$C$7)-($B36*$C$8*(1+$C$12)+$C$10+$C$11-$C$9)))/($B36*$C$8*(1+$C$12)+$C$10+$C$11-$C$9),0) -> 2.2739087 | F36: =IFERROR(((F$33*$C$6-$C$7)-$C$13*MAX(0,(F$33*$C$6-$C$7)-($B36*$C$8*(1+$C$12)+$C$10+$C$11-$C$9)))/($B36*$C$8*(1+$C$12)+$C$10+$C$11-$C$9),0) -> 2.519485 | G36: =IFERROR(((G$33*$C$6-$C$7)-$C$13*MAX(0,(G$33*$C$6-$C$7)-($B36*$C$8*(1+$C$12)+$C$10+$C$11-$C$9)))/($B36*$C$8*(1+$C$12)+$C$10+$C$11-$C$9),0) -> 2.7650613
B37: =$C$14+0*$C$17 -> 11 | C37: =IFERROR(((C$33*$C$6-$C$7)-$C$13*MAX(0,(C$33*$C$6-$C$7)-($B37*$C$8*(1+$C$12)+$C$10+$C$11-$C$9)))/($B37*$C$8*(1+$C$12)+$C$10+$C$11-$C$9),0) -> 1.6398382 | D37: =IFERROR(((D$33*$C$6-$C$7)-$C$13*MAX(0,(D$33*$C$6-$C$7)-($B37*$C$8*(1+$C$12)+$C$10+$C$11-$C$9)))/($B37*$C$8*(1+$C$12)+$C$10+$C$11-$C$9),0) -> 1.8648024 | E37: =IFERROR(((E$33*$C$6-$C$7)-$C$13*MAX(0,(E$33*$C$6-$C$7)-($B37*$C$8*(1+$C$12)+$C$10+$C$11-$C$9)))/($B37*$C$8*(1+$C$12)+$C$10+$C$11-$C$9),0) -> 2.0897666 | F37: =IFERROR(((F$33*$C$6-$C$7)-$C$13*MAX(0,(F$33*$C$6-$C$7)-($B37*$C$8*(1+$C$12)+$C$10+$C$11-$C$9)))/($B37*$C$8*(1+$C$12)+$C$10+$C$11-$C$9),0) -> 2.3147309 | G37: =IFERROR(((G$33*$C$6-$C$7)-$C$13*MAX(0,(G$33*$C$6-$C$7)-($B37*$C$8*(1+$C$12)+$C$10+$C$11-$C$9)))/($B37*$C$8*(1+$C$12)+$C$10+$C$11-$C$9),0) -> 2.5396951
B38: =$C$14+1*$C$17 -> 11.5 | C38: =IFERROR(((C$33*$C$6-$C$7)-$C$13*MAX(0,(C$33*$C$6-$C$7)-($B38*$C$8*(1+$C$12)+$C$10+$C$11-$C$9)))/($B38*$C$8*(1+$C$12)+$C$10+$C$11-$C$9),0) -> 1.5190536 | D38: =IFERROR(((D$33*$C$6-$C$7)-$C$13*MAX(0,(D$33*$C$6-$C$7)-($B38*$C$8*(1+$C$12)+$C$10+$C$11-$C$9)))/($B38*$C$8*(1+$C$12)+$C$10+$C$11-$C$9),0) -> 1.7265979 | E38: =IFERROR(((E$33*$C$6-$C$7)-$C$13*MAX(0,(E$33*$C$6-$C$7)-($B38*$C$8*(1+$C$12)+$C$10+$C$11-$C$9)))/($B38*$C$8*(1+$C$12)+$C$10+$C$11-$C$9),0) -> 1.9341423 | F38: =IFERROR(((F$33*$C$6-$C$7)-$C$13*MAX(0,(F$33*$C$6-$C$7)-($B38*$C$8*(1+$C$12)+$C$10+$C$11-$C$9)))/($B38*$C$8*(1+$C$12)+$C$10+$C$11-$C$9),0) -> 2.1416866 | G38: =IFERROR(((G$33*$C$6-$C$7)-$C$13*MAX(0,(G$33*$C$6-$C$7)-($B38*$C$8*(1+$C$12)+$C$10+$C$11-$C$9)))/($B38*$C$8*(1+$C$12)+$C$10+$C$11-$C$9),0) -> 2.3492309
B39: =$C$14+2*$C$17 -> 12 | C39: =IFERROR(((C$33*$C$6-$C$7)-$C$13*MAX(0,(C$33*$C$6-$C$7)-($B39*$C$8*(1+$C$12)+$C$10+$C$11-$C$9)))/($B39*$C$8*(1+$C$12)+$C$10+$C$11-$C$9),0) -> 1.4156303 | D39: =IFERROR(((D$33*$C$6-$C$7)-$C$13*MAX(0,(D$33*$C$6-$C$7)-($B39*$C$8*(1+$C$12)+$C$10+$C$11-$C$9)))/($B39*$C$8*(1+$C$12)+$C$10+$C$11-$C$9),0) -> 1.6082587 | E39: =IFERROR(((E$33*$C$6-$C$7)-$C$13*MAX(0,(E$33*$C$6-$C$7)-($B39*$C$8*(1+$C$12)+$C$10+$C$11-$C$9)))/($B39*$C$8*(1+$C$12)+$C$10+$C$11-$C$9),0) -> 1.800887 | F39: =IFERROR(((F$33*$C$6-$C$7)-$C$13*MAX(0,(F$33*$C$6-$C$7)-($B39*$C$8*(1+$C$12)+$C$10+$C$11-$C$9)))/($B39*$C$8*(1+$C$12)+$C$10+$C$11-$C$9),0) -> 1.9935154 | G39: =IFERROR(((G$33*$C$6-$C$7)-$C$13*MAX(0,(G$33*$C$6-$C$7)-($B39*$C$8*(1+$C$12)+$C$10+$C$11-$C$9)))/($B39*$C$8*(1+$C$12)+$C$10+$C$11-$C$9),0) -> 2.1861437
B40: =$C$14+3*$C$17 -> 12.5 | C40: =IFERROR(((C$33*$C$6-$C$7)-$C$13*MAX(0,(C$33*$C$6-$C$7)-($B40*$C$8*(1+$C$12)+$C$10+$C$11-$C$9)))/($B40*$C$8*(1+$C$12)+$C$10+$C$11-$C$9),0) -> 1.3260762 | D40: =IFERROR(((D$33*$C$6-$C$7)-$C$13*MAX(0,(D$33*$C$6-$C$7)-($B40*$C$8*(1+$C$12)+$C$10+$C$11-$C$9)))/($B40*$C$8*(1+$C$12)+$C$10+$C$11-$C$9),0) -> 1.5057887 | E40: =IFERROR(((E$33*$C$6-$C$7)-$C$13*MAX(0,(E$33*$C$6-$C$7)-($B40*$C$8*(1+$C$12)+$C$10+$C$11-$C$9)))/($B40*$C$8*(1+$C$12)+$C$10+$C$11-$C$9),0) -> 1.6855013 | F40: =IFERROR(((F$33*$C$6-$C$7)-$C$13*MAX(0,(F$33*$C$6-$C$7)-($B40*$C$8*(1+$C$12)+$C$10+$C$11-$C$9)))/($B40*$C$8*(1+$C$12)+$C$10+$C$11-$C$9),0) -> 1.8652139 | G40: =IFERROR(((G$33*$C$6-$C$7)-$C$13*MAX(0,(G$33*$C$6-$C$7)-($B40*$C$8*(1+$C$12)+$C$10+$C$11-$C$9)))/($B40*$C$8*(1+$C$12)+$C$10+$C$11-$C$9),0) -> 2.0449265
B43: Table 3: Sponsor IRR, exit year (rows) vs exit multiple (columns), base entry
B44: Year \ Exit | C44: =$C$15+-2*$C$18 -> 9 | D44: =$C$15+-1*$C$18 -> 10 | E44: =$C$15+0*$C$18 -> 11 | F44: =$C$15+1*$C$18 -> 12 | G44: =$C$15+2*$C$18 -> 13
B45: 3 | C45: =IF(((C$44*INDEX('Operating Model'!$D$9:$H$9,$B45)-INDEX('Debt Schedule'!$D$35:$H$35,$B45))-$C$13*MAX(0,(C$44*INDEX('Operating Model'!$D$9:$H$9,$B45)-INDEX('Debt Schedule'!$D$35:$H$35,$B45))-$C$16))>0,(((C$44*INDEX('Operating Model'!$D$9:$H$9,$B45)-INDEX('Debt Schedule'!$D$35:$H$35,$B45))-$C$13*MAX(0,(C$44*INDEX('Operating Model'!$D$9:$H$9,$B45)-INDEX('Debt Schedule'!$D$35:$H$35,$B45))-$C$16))/$C$16)^(1/$B45)-1,-1) -> 0.066746793 | D45: =IF(((D$44*INDEX('Operating Model'!$D$9:$H$9,$B45)-INDEX('Debt Schedule'!$D$35:$H$35,$B45))-$C$13*MAX(0,(D$44*INDEX('Operating Model'!$D$9:$H$9,$B45)-INDEX('Debt Schedule'!$D$35:$H$35,$B45))-$C$16))>0,(((D$44*INDEX('Operating Model'!$D$9:$H$9,$B45)-INDEX('Debt Schedule'!$D$35:$H$35,$B45))-$C$13*MAX(0,(D$44*INDEX('Operating Model'!$D$9:$H$9,$B45)-INDEX('Debt Schedule'!$D$35:$H$35,$B45))-$C$16))/$C$16)^(1/$B45)-1,-1) -> 0.12172608 | E45: =IF(((E$44*INDEX('Operating Model'!$D$9:$H$9,$B45)-INDEX('Debt Schedule'!$D$35:$H$35,$B45))-$C$13*MAX(0,(E$44*INDEX('Operating Model'!$D$9:$H$9,$B45)-INDEX('Debt Schedule'!$D$35:$H$35,$B45))-$C$16))>0,(((E$44*INDEX('Operating Model'!$D$9:$H$9,$B45)-INDEX('Debt Schedule'!$D$35:$H$35,$B45))-$C$13*MAX(0,(E$44*INDEX('Operating Model'!$D$9:$H$9,$B45)-INDEX('Debt Schedule'!$D$35:$H$35,$B45))-$C$16))/$C$16)^(1/$B45)-1,-1) -> 0.17178729 | F45: =IF(((F$44*INDEX('Operating Model'!$D$9:$H$9,$B45)-INDEX('Debt Schedule'!$D$35:$H$35,$B45))-$C$13*MAX(0,(F$44*INDEX('Operating Model'!$D$9:$H$9,$B45)-INDEX('Debt Schedule'!$D$35:$H$35,$B45))-$C$16))>0,(((F$44*INDEX('Operating Model'!$D$9:$H$9,$B45)-INDEX('Debt Schedule'!$D$35:$H$35,$B45))-$C$13*MAX(0,(F$44*INDEX('Operating Model'!$D$9:$H$9,$B45)-INDEX('Debt Schedule'!$D$35:$H$35,$B45))-$C$16))/$C$16)^(1/$B45)-1,-1) -> 0.21790165 | G45: =IF(((G$44*INDEX('Operating Model'!$D$9:$H$9,$B45)-INDEX('Debt Schedule'!$D$35:$H$35,$B45))-$C$13*MAX(0,(G$44*INDEX('Operating Model'!$D$9:$H$9,$B45)-INDEX('Debt Schedule'!$D$35:$H$35,$B45))-$C$16))>0,(((G$44*INDEX('Operating Model'!$D$9:$H$9,$B45)-INDEX('Debt Schedule'!$D$35:$H$35,$B45))-$C$13*MAX(0,(G$44*INDEX('Operating Model'!$D$9:$H$9,$B45)-INDEX('Debt Schedule'!$D$35:$H$35,$B45))-$C$16))/$C$16)^(1/$B45)-1,-1) -> 0.26076568
B46: 4 | C46: =IF(((C$44*INDEX('Operating Model'!$D$9:$H$9,$B46)-INDEX('Debt Schedule'!$D$35:$H$35,$B46))-$C$13*MAX(0,(C$44*INDEX('Operating Model'!$D$9:$H$9,$B46)-INDEX('Debt Schedule'!$D$35:$H$35,$B46))-$C$16))>0,(((C$44*INDEX('Operating Model'!$D$9:$H$9,$B46)-INDEX('Debt Schedule'!$D$35:$H$35,$B46))-$C$13*MAX(0,(C$44*INDEX('Operating Model'!$D$9:$H$9,$B46)-INDEX('Debt Schedule'!$D$35:$H$35,$B46))-$C$16))/$C$16)^(1/$B46)-1,-1) -> 0.096980789 | D46: =IF(((D$44*INDEX('Operating Model'!$D$9:$H$9,$B46)-INDEX('Debt Schedule'!$D$35:$H$35,$B46))-$C$13*MAX(0,(D$44*INDEX('Operating Model'!$D$9:$H$9,$B46)-INDEX('Debt Schedule'!$D$35:$H$35,$B46))-$C$16))>0,(((D$44*INDEX('Operating Model'!$D$9:$H$9,$B46)-INDEX('Debt Schedule'!$D$35:$H$35,$B46))-$C$13*MAX(0,(D$44*INDEX('Operating Model'!$D$9:$H$9,$B46)-INDEX('Debt Schedule'!$D$35:$H$35,$B46))-$C$16))/$C$16)^(1/$B46)-1,-1) -> 0.13548183 | E46: =IF(((E$44*INDEX('Operating Model'!$D$9:$H$9,$B46)-INDEX('Debt Schedule'!$D$35:$H$35,$B46))-$C$13*MAX(0,(E$44*INDEX('Operating Model'!$D$9:$H$9,$B46)-INDEX('Debt Schedule'!$D$35:$H$35,$B46))-$C$16))>0,(((E$44*INDEX('Operating Model'!$D$9:$H$9,$B46)-INDEX('Debt Schedule'!$D$35:$H$35,$B46))-$C$13*MAX(0,(E$44*INDEX('Operating Model'!$D$9:$H$9,$B46)-INDEX('Debt Schedule'!$D$35:$H$35,$B46))-$C$16))/$C$16)^(1/$B46)-1,-1) -> 0.17042245 | F46: =IF(((F$44*INDEX('Operating Model'!$D$9:$H$9,$B46)-INDEX('Debt Schedule'!$D$35:$H$35,$B46))-$C$13*MAX(0,(F$44*INDEX('Operating Model'!$D$9:$H$9,$B46)-INDEX('Debt Schedule'!$D$35:$H$35,$B46))-$C$16))>0,(((F$44*INDEX('Operating Model'!$D$9:$H$9,$B46)-INDEX('Debt Schedule'!$D$35:$H$35,$B46))-$C$13*MAX(0,(F$44*INDEX('Operating Model'!$D$9:$H$9,$B46)-INDEX('Debt Schedule'!$D$35:$H$35,$B46))-$C$16))/$C$16)^(1/$B46)-1,-1) -> 0.20248744 | G46: =IF(((G$44*INDEX('Operating Model'!$D$9:$H$9,$B46)-INDEX('Debt Schedule'!$D$35:$H$35,$B46))-$C$13*MAX(0,(G$44*INDEX('Operating Model'!$D$9:$H$9,$B46)-INDEX('Debt Schedule'!$D$35:$H$35,$B46))-$C$16))>0,(((G$44*INDEX('Operating Model'!$D$9:$H$9,$B46)-INDEX('Debt Schedule'!$D$35:$H$35,$B46))-$C$13*MAX(0,(G$44*INDEX('Operating Model'!$D$9:$H$9,$B46)-INDEX('Debt Schedule'!$D$35:$H$35,$B46))-$C$16))/$C$16)^(1/$B46)-1,-1) -> 0.23217492
